import { User } from "../models/user.models.js";
import bcrypt from "bcrypt";

export const generateAccessAndRefreshToken = async (userId) => {
  try {
    const user = await User.findById(userId);
    if (!user) {
      throw new ApiError(404, "User not found for token generation");
    }

    const accessToken = user.generatingAccessToken();
    const refreshToken = user.generatingRefreshToken();

    user.refreshToken = refreshToken;
    await user.save({ validateBeforeSave: false });

    return { accessToken, refreshToken };
  } catch (err) {
    throw new ApiError(500, "Something went wrong while generating access token");
  }
};

export const registerUser = async (req, res, next) => {
  try {
    const { name, email, password } = req.body;

    if (!name || !email || !password) {
      return res.status(400).json({ message: "All fields are required" });
    }

    const existingUser = await User.findOne({ email });
    if (existingUser) {
      return res.status(409).json({ message: "User already exists" });
    }

    const user = await User.create({ name, email, password });

    res.status(201).json({
      message: "User registered successfully",
      user: { id: user._id, name: user.name, email: user.email },
    });
  } catch (err) {
    next(err);
  }
};

export const loginUser = async (req, res, next) => {
  try {
    const { email, password } = req.body;

    if (!email || !password) {
      return res.status(400).json({ message: "Email and password required" });
    }

    const user = await User.findOne({ email }).select("+password");
    if (!user) {
      return res.status(404).json({ message: "User not found" });
    }

    const isPasswordValid = await user.isPasswordCorrect(password);
    if (!isPasswordValid) {
      return res.status(401).json({ message: "Invalid password" });
    }

    res.status(200).json({
      message: "Login successful",
      user: { id: user._id, name: user.name, email: user.email },
    });
  } catch (err) {
    next(err);
  }
};
